Workbook
Name JiraExportFileLocation: #REF!
Name RAW_labels: OFFSET(INDEX('[1]raw export'!$1000:$1000, 2, [1]data!XFD$2), 0, 0, 1, 5)

Sheet Sprint Summary (standard)
I8: estimate (story points) | K8: throughput (no. of items)
H9: not completed in sprint | I9: ='Sprint Summary | data'!R18 -> 0 | J9: ='Sprint Summary | data'!S18 -> #DIV/0! | K9: ='Sprint Summary | data'!T18 -> 0 | L9: ='Sprint Summary | data'!U18 -> #DIV/0!
H10: completed in sprint | I10: ='Sprint Summary | data'!R19 -> 0 | J10: ='Sprint Summary | data'!S19 -> #DIV/0! | K10: ='Sprint Summary | data'!T19 -> 0 | L10: ='Sprint Summary | data'!U19 -> #DIV/0! | M10: =IF('Sprint Summary | data'!R28,1,0) -> 0
H11: TOTAL IN SPRINT | I11: ='Sprint Summary | data'!R20 -> 0 | J11: ='Sprint Summary | data'!S20 -> #DIV/0! | K11: ='Sprint Summary | data'!T20 -> 0 | L11: ='Sprint Summary | data'!U20 -> #DIV/0! | M11: =IF('Sprint Summary | data'!R29,1,0) -> 0
H12: committed at sprint start (+) | I12: ='Sprint Summary | data'!R21 -> 0 | J12: ='Sprint Summary | data'!S21 -> #DIV/0! | K12: ='Sprint Summary | data'!T21 -> 0 | L12: ='Sprint Summary | data'!U21 -> #DIV/0!
H13: added after sprint start (+) | I13: ='Sprint Summary | data'!R22 -> 0 | J13: ='Sprint Summary | data'!S22 -> #DIV/0! | K13: ='Sprint Summary | data'!T22 -> 0 | L13: ='Sprint Summary | data'!U22 -> #DIV/0!
H14: removed from sprint (-) | I14: ='Sprint Summary | data'!R23 -> 0 | J14: ='Sprint Summary | data'!S23 -> #DIV/0! | K14: ='Sprint Summary | data'!T23 -> 0 | L14: ='Sprint Summary | data'!U23 -> #DIV/0!

Sheet Sprint Summary (metadata)
I8: estimate (story points) | K8: throughput (no. of items)
H9: not completed in sprint | I9: ='Sprint Summary | data'!R18 -> 0 | J9: ='Sprint Summary | data'!S18 -> #DIV/0! | K9: ='Sprint Summary | data'!T18 -> 0 | L9: ='Sprint Summary | data'!U18 -> #DIV/0!
H10: completed in sprint | I10: ='Sprint Summary | data'!R19 -> 0 | J10: ='Sprint Summary | data'!S19 -> #DIV/0! | K10: ='Sprint Summary | data'!T19 -> 0 | L10: ='Sprint Summary | data'!U19 -> #DIV/0! | M10: =IF('Sprint Summary | data'!R28,1,0) -> 0
H11: TOTAL IN SPRINT | I11: ='Sprint Summary | data'!R20 -> 0 | J11: ='Sprint Summary | data'!S20 -> #DIV/0! | K11: ='Sprint Summary | data'!T20 -> 0 | L11: ='Sprint Summary | data'!U20 -> #DIV/0! | M11: =IF('Sprint Summary | data'!R29,1,0) -> 0
H12: committed at sprint start (+) | I12: ='Sprint Summary | data'!R21 -> 0 | J12: ='Sprint Summary | data'!S21 -> #DIV/0! | K12: ='Sprint Summary | data'!T21 -> 0 | L12: ='Sprint Summary | data'!U21 -> #DIV/0!
H13: added after sprint start (+) | I13: ='Sprint Summary | data'!R22 -> 0 | J13: ='Sprint Summary | data'!S22 -> #DIV/0! | K13: ='Sprint Summary | data'!T22 -> 0 | L13: ='Sprint Summary | data'!U22 -> #DIV/0!
H14: removed from sprint (-) | I14: ='Sprint Summary | data'!R23 -> 0 | J14: ='Sprint Summary | data'!S23 -> #DIV/0! | K14: ='Sprint Summary | data'!T23 -> 0 | L14: ='Sprint Summary | data'!U23 -> #DIV/0!

Sheet Sprint Summary | data
A1: Sprint Summary | Data
A2: stats used by Sprint Summary presentation.
A4: sprint summary
A5: squad name | B5: ='Calculated Stats'!C22 -> 0
A6: sprint name | B6: ='processed | data'!B6 -> 0
A7: date range | B7: =_xlfn.CONCAT('Calculated Stats'!C23, " - ", 'Calculated Stats'!C24) -> 00/01/1900 - 00/01/1900
M8: capacity guide
M9: trend | N9: ='Calculated Stats'!C143 -> 0
M10: target | N10: ='Calculated Stats'!C140 -> 0
A13: burnup chart | I13: sprint completion | Q13: Sprint Progress
A15: screenshot
I16: total in sprint | J16: ='Calculated Stats'!C108 -> 0 | R16: estimate (story points) | T16: throughput (no. of items)
R17: totals | S17: % | T17: totals | U17: %
I18: CHART: complete vs total | Q18: not completed in sprint | R18: ='Calculated Stats'!C106 -> 0 | S18: =_xlfn.CONCAT('Calculated Stats'!D106, "%") -> #DIV/0! | T18: ='Calculated Stats'!E106 -> 0 | U18: =_xlfn.CONCAT('Calculated Stats'!F106,"%") -> #DIV/0!
A19: sprint velocity trends | I19: done | J19: ='Calculated Stats'!C107 -> 0 | Q19: completed in sprint | R19: ='Calculated Stats'!C107 -> 0 | S19: =_xlfn.CONCAT('Calculated Stats'!D107,"%") -> #DIV/0! | T19: ='Calculated Stats'!E107 -> 0 | U19: =_xlfn.CONCAT('Calculated Stats'!F107,"%") -> #DIV/0!
I20: incomplete | J20: ='Calculated Stats'!C106 -> 0 | Q20: TOTAL IN THE SPRINT | R20: ='Calculated Stats'!C108 -> 0 | S20: =_xlfn.CONCAT('Calculated Stats'!D108,"%") -> #DIV/0! | T20: ='Calculated Stats'!E108 -> 0 | U20: =_xlfn.CONCAT('Calculated Stats'!F108,"%") -> #DIV/0!
A21: screenshot | Q21: committed at sprint start | R21: ='Calculated Stats'!C109 -> 0 | S21: =_xlfn.CONCAT('Calculated Stats'!D109,"%") -> #DIV/0! | T21: ='Calculated Stats'!E109 -> 0 | U21: =_xlfn.CONCAT('Calculated Stats'!F109,"%") -> #DIV/0!
Q22: added after sprint start | R22: ='Calculated Stats'!C110 -> 0 | S22: =_xlfn.CONCAT('Calculated Stats'!D110,"%") -> #DIV/0! | T22: ='Calculated Stats'!E110 -> 0 | U22: =_xlfn.CONCAT('Calculated Stats'!F110,"%") -> #DIV/0!
I23: CHART: done vs WIP | Q23: removed from sprint | R23: ='Calculated Stats'!C111 -> 0 | S23: =_xlfn.CONCAT('Calculated Stats'!D111,"%") -> #DIV/0! | T23: ='Calculated Stats'!E111 -> 0 | U23: =_xlfn.CONCAT('Calculated Stats'!F111,"%") -> #DIV/0!
I24: not started | J24: ='Calculated Stats'!C117 -> 0
I25: WIP | J25: ='Calculated Stats'!C118 -> 0
A26: delivery allocation | outcomes | I26: done | J26: ='Calculated Stats'!C119 -> 0 | Q26: insight
A27: SUM | B27: =SUM(B29:B31) -> 0
B28: total | C28: % | Q28: healthy performance trend | R28: ='Calculated Stats'!C146 -> 0
A29: =_xlfn.CONCAT('Calculated Stats'!B127, "/", 'Calculated Stats'!B128) -> BAU/Improvement | B29: ='Calculated Stats'!C130 -> 0 | C29: =ROUND(B29/B$27*100,0) -> #DIV/0! | I29: BACKGROUND: capacity vs trend | Q29: achievable sprint goal | R29: ='Calculated Stats'!C145 -> 0
A30: ='Calculated Stats'!B10 -> label3 | B30: =INDEX('Calculated Stats'!D$36:D$45, MATCH(A30, 'Calculated Stats'!B$36:B$45, 0)) -> 0 | C30: =ROUND(B30/B$27*100,0) -> #DIV/0!
A31: ='Calculated Stats'!B11 -> label4 | B31: =INDEX('Calculated Stats'!D$36:D$45, MATCH(A31, 'Calculated Stats'!B$36:B$45, 0)) -> 0 | C31: =ROUND(B31/B$27*100,0) -> #DIV/0! | J31: ='Calculated Stats'!C108 -> 0 | K31: total in sprint
I32: capacity trend | J32: ='Calculated Stats'!C143 -> 0
I33: sprint capacity | J33: ='Calculated Stats'!C140 -> 0
I37: work item granularity | Q37: delivery allocation | streams
Q38: total | R38: =SUM(R40:R44) -> 0
S39: %
I40: points | J40: ='Calculated Stats'!C134 -> 0 | Q40: ='Calculated Stats'!C8 -> component1 | R40: =INDEX('Calculated Stats'!D$66:D$75, MATCH(Q40, 'Calculated Stats'!B$66:B$75, 0)) -> 0 | S40: =ROUND(R40/R$38*100,0) -> #DIV/0!
I41: items | J41: 1 | Q41: ='Calculated Stats'!C9 -> component2 | R41: =INDEX('Calculated Stats'!D$66:D$75, MATCH(Q41, 'Calculated Stats'!B$66:B$75, 0)) -> 0 | S41: =ROUND(R41/R$38*100,0) -> #DIV/0!
Q42: ='Calculated Stats'!C10 -> component3 | R42: =INDEX('Calculated Stats'!D$66:D$75, MATCH(Q42, 'Calculated Stats'!B$66:B$75, 0)) -> 0 | S42: =ROUND(R42/R$38*100,0) -> #DIV/0!
I43: total work items completed | J43: ='Calculated Stats'!E107 -> 0
I44: total story points completed | J44: ='Calculated Stats'!C107 -> 0
I48: unestimated work
J49: %
I50: % items | J50: ='Calculated Stats'!C135 -> 0
...

Sheet Calculated Stats
B1: Calculated Stats
B2: stats calculated based on cleaned data
B6: [Optional] Configure the metadata for meta data template. List below the labels and components you need to report on. (DON’T Edit BAU/Improvement labels)
B7: Labels | C7: Components
B8: BAU | C8: component1
B9: Improvement | C9: component2
B10: label3 | C10: component3
B11: label4
B12: 5 | C12: 5
B13: 6 | C13: 6
B14: 7 | C14: 7
B15: 8 | C15: 8
B16: 9 | C16: 9
B17: 10 | C17: 10
B20: Sprint Details
B21: Sprint name | C21: ='processed | data'!B6 -> 0
B22: squad name | C22: ='processed | data'!B7 -> 0
B23: sprint start date | C23: =TEXT('processed | data'!B8, "DD/MM/YYYY") -> 00/01/1900
B24: sprint end date | C24: =TEXT('processed | data'!B9, "DD/MM/YYYY") -> 00/01/1900
B32: Data in these tables is pulled in from processed | data sheet
B34: Streams (labels) | C34: story points
B35: DON’T EDIT THIS LIST (USE CONFIG ABOVE) | C35: total in sprint | D35: done
B36: =B8 -> BAU | C36: ='processed | data'!B17 -> 0 | D36: ='processed | data'!B29 -> 0
B37: =B9 -> Improvement | C37: ='processed | data'!B18 -> 0 | D37: ='processed | data'!B30 -> 0
B38: =B10 -> label3 | C38: ='processed | data'!B19 -> 0 | D38: ='processed | data'!B31 -> 0
B39: =B11 -> label4 | C39: ='processed | data'!B20 -> 0 | D39: ='processed | data'!B32 -> 0
B40: =B12 -> 5 | C40: ='processed | data'!B21 -> 0 | D40: ='processed | data'!B33 -> 0
B41: =B13 -> 6 | C41: ='processed | data'!B22 -> 0 | D41: ='processed | data'!B34 -> 0
B42: =B14 -> 7 | C42: ='processed | data'!B23 -> 0 | D42: ='processed | data'!B35 -> 0
B43: =B15 -> 8 | C43: ='processed | data'!B26 -> 0 | D43: ='processed | data'!B36 -> 0
B44: =B16 -> 9 | C44: ='processed | data'!B27 -> 0 | D44: ='processed | data'!B37 -> 0
B45: =B17 -> 10 | C45: ='processed | data'!B28 -> 0 | D45: ='processed | data'!B38 -> 0
B49: Streams (labels) | C49: throughput
B50: DON’T EDIT THIS LIST (USE CONFIG ABOVE) | C50: total in sprint | D50: done
B51: =B8 -> BAU | C51: ='processed | data'!B68 -> 0 | D51: ='processed | data'!B80 -> 0
B52: =B9 -> Improvement | C52: ='processed | data'!B69 -> 0 | D52: ='processed | data'!B81 -> 0
B53: =B10 -> label3 | C53: ='processed | data'!B70 -> 0 | D53: ='processed | data'!B82 -> 0
B54: =B11 -> label4 | C54: ='processed | data'!B71 -> 0 | D54: ='processed | data'!B83 -> 0
B55: =B12 -> 5 | C55: ='processed | data'!B72 -> 0 | D55: ='processed | data'!B84 -> 0
B56: =B13 -> 6 | C56: ='processed | data'!B73 -> 0 | D56: ='processed | data'!B85 -> 0
...

Sheet processed | data
A1: Processed Data
A2: calculated stats imported from csv
A4: Sprint Details
A5: Sprint Details | D5: csv field | E5: csv column index
A6: Sprint name | B6: {=IFERROR(INDEX('rawdata | iteration analysis'!$2:$2, E6), 0)} -> 0 | D6: sprintName | E6: =MATCH(D6, 'rawdata | iteration analysis'!$1:$1, ) -> #N/A
A7: squad name | B7: {=IFERROR(INDEX('rawdata | iteration analysis'!$2:$2, E7), 0)} -> 0 | D7: squadName | E7: =MATCH(D7, 'rawdata | iteration analysis'!$1:$1, ) -> #N/A
A8: sprint start date | B8: {=IFERROR(INDEX('rawdata | iteration analysis'!$2:$2, E8), 0)} -> 0 | D8: sprintDate_start | E8: =MATCH(D8, 'rawdata | iteration analysis'!$1:$1, ) -> #N/A
A9: sprint end date | B9: {=IFERROR(INDEX('rawdata | iteration analysis'!$2:$2, E9), 0)} -> 0 | D9: sprintDate_end | E9: =MATCH(D9, 'rawdata | iteration analysis'!$1:$1, ) -> #N/A
A15: Metadata | D15: storyPoints
A16: Labels (total in sprint) | B16: value | D16: csv field | E16: csv column index
A17: ='Calculated Stats'!B8 -> BAU | B17: {=IFERROR(INDEX('rawdata | iteration analysis'!$2:$2, E17), 0)} -> 0 | D17: =_xlfn.CONCAT("labels_", A17,"_",D$15) -> labels_BAU_storyPoints | E17: =MATCH(D17, 'rawdata | iteration analysis'!$1:$1, ) -> #N/A
A18: ='Calculated Stats'!B9 -> Improvement | B18: {=IFERROR(INDEX('rawdata | iteration analysis'!$2:$2, E18), 0)} -> 0 | D18: =_xlfn.CONCAT("labels_", A18,"_",D$15) -> labels_Improvement_storyPoints | E18: =MATCH(D18, 'rawdata | iteration analysis'!$1:$1, ) -> #N/A
A19: ='Calculated Stats'!B10 -> label3 | B19: {=IFERROR(INDEX('rawdata | iteration analysis'!$2:$2, E19), 0)} -> 0 | D19: =_xlfn.CONCAT("labels_", A19,"_",D$15) -> labels_label3_storyPoints | E19: =MATCH(D19, 'rawdata | iteration analysis'!$1:$1, ) -> #N/A
A20: ='Calculated Stats'!B11 -> label4 | B20: {=IFERROR(INDEX('rawdata | iteration analysis'!$2:$2, E20), 0)} -> 0 | D20: =_xlfn.CONCAT("labels_", A20, "_",D$15) -> labels_label4_storyPoints | E20: =MATCH(D20, 'rawdata | iteration analysis'!$1:$1, ) -> #N/A
A21: ='Calculated Stats'!B12 -> 5 | B21: {=IFERROR(INDEX('rawdata | iteration analysis'!$2:$2, E21), 0)} -> 0 | D21: =_xlfn.CONCAT("labels_", A21,"_",D$15) -> labels_5_storyPoints | E21: =MATCH(D21, 'rawdata | iteration analysis'!$1:$1, ) -> #N/A
A22: ='Calculated Stats'!B13 -> 6 | B22: {=IFERROR(INDEX('rawdata | iteration analysis'!$2:$2, E22), 0)} -> 0 | D22: =_xlfn.CONCAT("labels_", A22, "_",D$15) -> labels_6_storyPoints | E22: =MATCH(D22, 'rawdata | iteration analysis'!$1:$1, ) -> #N/A
A23: ='Calculated Stats'!B14 -> 7 | B23: {=IFERROR(INDEX('rawdata | iteration analysis'!$2:$2, E23), 0)} -> 0 | D23: =_xlfn.CONCAT("labels_", A23,"_",D$15) -> labels_7_storyPoints | E23: =MATCH(D23, 'rawdata | iteration analysis'!$1:$1, ) -> #N/A
A24: ='Calculated Stats'!B15 -> 8 | B24: {=IFERROR(INDEX('rawdata | iteration analysis'!$2:$2, E24), 0)} -> 0 | D24: =_xlfn.CONCAT("labels_", A24,"_",D$15) -> labels_8_storyPoints | E24: =MATCH(D24, 'rawdata | iteration analysis'!$1:$1, ) -> #N/A
A25: ='Calculated Stats'!B16 -> 9 | B25: {=IFERROR(INDEX('rawdata | iteration analysis'!$2:$2, E25), 0)} -> 0 | D25: =_xlfn.CONCAT("labels_", A25,"_",D$15) -> labels_9_storyPoints | E25: =MATCH(D25, 'rawdata | iteration analysis'!$1:$1, ) -> #N/A
A26: ='Calculated Stats'!B17 -> 10 | B26: {=IFERROR(INDEX('rawdata | iteration analysis'!$2:$2, E26), 0)} -> 0 | D26: =_xlfn.CONCAT("labels_", A26,"_",D$15) -> labels_10_storyPoints | E26: =MATCH(D26, 'rawdata | iteration analysis'!$1:$1, ) -> #N/A
A28: Labels (done) | D28: csv field | E28: csv column index
A29: ='Calculated Stats'!B8 -> BAU | B29: {=IFERROR(INDEX('rawdata | iteration analysis'!$2:$2, E29), 0)} -> 0 | D29: =_xlfn.CONCAT("completedLabels_", A29,"_",D$15) -> completedLabels_BAU_storyPoints | E29: =MATCH(D29, 'rawdata | iteration analysis'!$1:$1, ) -> #N/A
A30: ='Calculated Stats'!B9 -> Improvement | B30: {=IFERROR(INDEX('rawdata | iteration analysis'!$2:$2, E30), 0)} -> 0 | D30: =_xlfn.CONCAT("completedLabels_", A30,"_",D$15) -> completedLabels_Improvement_storyPoints | E30: =MATCH(D30, 'rawdata | iteration analysis'!$1:$1, ) -> #N/A
A31: ='Calculated Stats'!B10 -> label3 | B31: {=IFERROR(INDEX('rawdata | iteration analysis'!$2:$2, E31), 0)} -> 0 | D31: =_xlfn.CONCAT("completedLabels_", A31,"_",D$15) -> completedLabels_label3_storyPoints | E31: =MATCH(D31, 'rawdata | iteration analysis'!$1:$1, ) -> #N/A
A32: ='Calculated Stats'!B11 -> label4 | B32: {=IFERROR(INDEX('rawdata | iteration analysis'!$2:$2, E32), 0)} -> 0 | D32: =_xlfn.CONCAT("completedLabels_", A32,"_",D$15) -> completedLabels_label4_storyPoints | E32: =MATCH(D32, 'rawdata | iteration analysis'!$1:$1, ) -> #N/A
A33: ='Calculated Stats'!B12 -> 5 | B33: {=IFERROR(INDEX('rawdata | iteration analysis'!$2:$2, E33), 0)} -> 0 | D33: =_xlfn.CONCAT("completedLabels_", A33,"_",D$15) -> completedLabels_5_storyPoints | E33: =MATCH(D33, 'rawdata | iteration analysis'!$1:$1, ) -> #N/A
A34: ='Calculated Stats'!B13 -> 6 | B34: {=IFERROR(INDEX('rawdata | iteration analysis'!$2:$2, E34), 0)} -> 0 | D34: =_xlfn.CONCAT("completedLabels_", A34,"_",D$15) -> completedLabels_6_storyPoints | E34: =MATCH(D34, 'rawdata | iteration analysis'!$1:$1, ) -> #N/A
A35: ='Calculated Stats'!B14 -> 7 | B35: {=IFERROR(INDEX('rawdata | iteration analysis'!$2:$2, E35), 0)} -> 0 | D35: =_xlfn.CONCAT("completedLabels_", A35,"_",D$15) -> completedLabels_7_storyPoints | E35: =MATCH(D35, 'rawdata | iteration analysis'!$1:$1, ) -> #N/A
A36: ='Calculated Stats'!B15 -> 8 | B36: {=IFERROR(INDEX('rawdata | iteration analysis'!$2:$2, E36), 0)} -> 0 | D36: =_xlfn.CONCAT("completedLabels_", A36,"_",D$15) -> completedLabels_8_storyPoints | E36: =MATCH(D36, 'rawdata | iteration analysis'!$1:$1, ) -> #N/A
A37: ='Calculated Stats'!B16 -> 9 | B37: {=IFERROR(INDEX('rawdata | iteration analysis'!$2:$2, E37), 0)} -> 0 | D37: =_xlfn.CONCAT("completedLabels_", A37,"_",D$15) -> completedLabels_9_storyPoints | E37: =MATCH(D37, 'rawdata | iteration analysis'!$1:$1, ) -> #N/A
A38: ='Calculated Stats'!B17 -> 10 | B38: {=IFERROR(INDEX('rawdata | iteration analysis'!$2:$2, E38), 0)} -> 0 | D38: =_xlfn.CONCAT("completedLabels_", A38,"_",D$15) -> completedLabels_10_storyPoints | E38: =MATCH(D38, 'rawdata | iteration analysis'!$1:$1, ) -> #N/A
A40: Components (total in sprint) | D40: csv field | E40: csv column index
A41: ='Calculated Stats'!C8 -> component1 | B41: {=IFERROR(INDEX('rawdata | iteration analysis'!$2:$2, E41), 0)} -> 0 | D41: =_xlfn.CONCAT("components_", A41,"_",D$15) -> components_component1_storyPoints | E41: =MATCH(D41, 'rawdata | iteration analysis'!$1:$1, ) -> #N/A
A42: ='Calculated Stats'!C9 -> component2 | B42: {=IFERROR(INDEX('rawdata | iteration analysis'!$2:$2, E42), 0)} -> 0 | D42: =_xlfn.CONCAT("components_", A42,"_",D$15) -> components_component2_storyPoints | E42: =MATCH(D42, 'rawdata | iteration analysis'!$1:$1, ) -> #N/A
A43: ='Calculated Stats'!C10 -> component3 | B43: {=IFERROR(INDEX('rawdata | iteration analysis'!$2:$2, E43), 0)} -> 0 | D43: =_xlfn.CONCAT("components_", A43,"_",D$15) -> components_component3_storyPoints | E43: =MATCH(D43, 'rawdata | iteration analysis'!$1:$1, ) -> #N/A
A44: ='Calculated Stats'!C11 -> 0 | B44: {=IFERROR(INDEX('rawdata | iteration analysis'!$2:$2, E44), 0)} -> 0 | D44: =_xlfn.CONCAT("components_", A44,"_",D$15) -> components_0_storyPoints | E44: =MATCH(D44, 'rawdata | iteration analysis'!$1:$1, ) -> #N/A
A45: ='Calculated Stats'!C12 -> 5 | B45: {=IFERROR(INDEX('rawdata | iteration analysis'!$2:$2, E45), 0)} -> 0 | D45: =_xlfn.CONCAT("components_", A45,"_",D$15) -> components_5_storyPoints | E45: =MATCH(D45, 'rawdata | iteration analysis'!$1:$1, ) -> #N/A
A46: ='Calculated Stats'!C13 -> 6 | B46: {=IFERROR(INDEX('rawdata | iteration analysis'!$2:$2, E46), 0)} -> 0 | D46: =_xlfn.CONCAT("components_", A46,"_",D$15) -> components_6_storyPoints | E46: =MATCH(D46, 'rawdata | iteration analysis'!$1:$1, ) -> #N/A
A47: ='Calculated Stats'!C14 -> 7 | B47: {=IFERROR(INDEX('rawdata | iteration analysis'!$2:$2, E47), 0)} -> 0 | D47: =_xlfn.CONCAT("components_", A47,"_",D$15) -> components_7_storyPoints | E47: =MATCH(D47, 'rawdata | iteration analysis'!$1:$1, ) -> #N/A
A48: ='Calculated Stats'!C15 -> 8 | B48: {=IFERROR(INDEX('rawdata | iteration analysis'!$2:$2, E48), 0)} -> 0 | D48: =_xlfn.CONCAT("components_", A48,"_",D$15) -> components_8_storyPoints | E48: =MATCH(D48, 'rawdata | iteration analysis'!$1:$1, ) -> #N/A
...

Sheet rawdata | iteration analysis

Sheet Sheet2
A1: sprintName | B1: #1
A2: squadName | B2: ACME Squad
A3: sprintDate_start | B3: 36892
A4: sprintDate_end | B4: 37289
A5: sprintOverview_backlogSize_estimate | B5: 85
A6: sprintOverview_backlogSize_throughput | B6: 66
A7: sprintOverview_completedTotal_estimate | B7: 15.25
A8: sprintOverview_completedTotal_throughput | B8: 15
A9: sprintOverview_notCompletedInSprint_estimate | B9: 69.75
A10: sprintOverview_notCompletedInSprint_throughput | B10: 51
A11: sprintOverview_committedAtStartOfSprint_estimate | B11: 71
A12: sprintOverview_committedAtStartOfSprint_throughput | B12: 72
A13: sprintOverview_removedFromSprint_estimate | B13: 11
A14: sprintOverview_removedFromSprint_throughput | B14: 12
... A140: trends_velocityTrends_throughput | B140: 45
A141: insights_achievableSprintGoal_estimate | B141: FALSE
A142: insights_achievableSprintGoal_throughput | B142: FALSE
A143: insights_healthyPerformanceTarget_estimate | B143: FALSE
A144: insights_healthyPerformanceTarget_throughput | B144: FALSE
