Workbook
Name JiraExportFileLocation: #REF!
Name RAW_labels: OFFSET(INDEX('[1]raw export'!$1000:$1000, 2, [1]data!XFD$2), 0, 0, 1, 5)

Sheet Sprint Summary
H7: estimate (story points) | J7: throughput (no. of items)
G8: not completed in sprint | H8: ='Sprint Summary | data'!R18 -> 53 | I8: ='Sprint Summary | data'!S18 -> 67 | J8: ='Sprint Summary | data'!T18 -> 41 | K8: ='Sprint Summary | data'!U18 -> 64
G9: completed in sprint | H9: ='Sprint Summary | data'!R19 -> 26.5 | I9: ='Sprint Summary | data'!S19 -> 33 | J9: ='Sprint Summary | data'!T19 -> 23 | K9: ='Sprint Summary | data'!U19 -> 36 | L9: =IF('Sprint Summary | data'!R28,1,0) -> 0
G10: TOTAL IN SPRINT | H10: ='Sprint Summary | data'!R20 -> 79.5 | I10: ='Sprint Summary | data'!S20 -> 100 | J10: ='Sprint Summary | data'!T20 -> 64 | K10: ='Sprint Summary | data'!U20 -> 100 | L10: =IF('Sprint Summary | data'!R29,1,0) -> 0
G11: committed at sprint start (-) | H11: ='Sprint Summary | data'!R21 -> 72.5 | I11: ='Sprint Summary | data'!S21 -> 91 | J11: ='Sprint Summary | data'!T21 -> 63 | K11: ='Sprint Summary | data'!U21 -> 98
G12: added after sprint start (+) | H12: ='Sprint Summary | data'!R22 -> 22 | I12: ='Sprint Summary | data'!S22 -> 30 | J12: ='Sprint Summary | data'!T22 -> 10 | K12: ='Sprint Summary | data'!U22 -> 16
G13: removed from sprint (-) | H13: ='Sprint Summary | data'!R23 -> 15 | I13: ='Sprint Summary | data'!S23 -> 19 | J13: ='Sprint Summary | data'!T23 -> 9 | K13: ='Sprint Summary | data'!U23 -> 14

Sheet Sprint Summary | data
A1: Sprint Summary | Data
A2: stats used by Sprint Summary presentation.
A4: sprint summary
A6: sprint name | B6: ='processed | data'!B6 -> Q24-4.8
A7: date range | B7: =_xlfn.CONCAT('Calculated Stats'!C23, " - ", 'Calculated Stats'!C24) -> 03/07/2024 - 18/07/2024
M8: capacity guide
M9: trend | N9: ='Calculated Stats'!C143 -> 50
M10: target | N10: ='Calculated Stats'!C140 -> 50
A13: burnup chart | I13: sprint completion | Q13: Sprint Progress
A15: screenshot
I16: total in sprint | J16: ='Calculated Stats'!C108 -> 79.5 | R16: estimate (story points) | T16: throughput (no. of items)
R17: totals | S17: % | T17: totals | U17: %
I18: CHART: complete vs total | Q18: not completed in sprint | R18: ='Calculated Stats'!C106 -> 53 | S18: ='Calculated Stats'!D106 -> 67 | T18: ='Calculated Stats'!E106 -> 41 | U18: ='Calculated Stats'!F106 -> 64
A19: sprint velocity trends | I19: done | J19: ='Calculated Stats'!C107 -> 26.5 | Q19: completed in sprint | R19: ='Calculated Stats'!C107 -> 26.5 | S19: ='Calculated Stats'!D107 -> 33 | T19: ='Calculated Stats'!E107 -> 23 | U19: ='Calculated Stats'!F107 -> 36
I20: incomplete | J20: ='Calculated Stats'!C106 -> 53 | Q20: TOTAL IN THE SPRINT | R20: ='Calculated Stats'!C108 -> 79.5 | S20: ='Calculated Stats'!D108 -> 100 | T20: ='Calculated Stats'!E108 -> 64 | U20: ='Calculated Stats'!F108 -> 100
A21: screenshot | Q21: committed at sprint start | R21: ='Calculated Stats'!C109 -> 72.5 | S21: ='Calculated Stats'!D109 -> 91 | T21: ='Calculated Stats'!E109 -> 63 | U21: ='Calculated Stats'!F109 -> 98
Q22: added after sprint start | R22: ='Calculated Stats'!C110 -> 22 | S22: ='Calculated Stats'!D110 -> 30 | T22: ='Calculated Stats'!E110 -> 10 | U22: ='Calculated Stats'!F110 -> 16
I23: CHART: done vs WIP | Q23: removed from sprint | R23: ='Calculated Stats'!C111 -> 15 | S23: ='Calculated Stats'!D111 -> 19 | T23: ='Calculated Stats'!E111 -> 9 | U23: ='Calculated Stats'!F111 -> 14
I24: not started | J24: ='Calculated Stats'!C117 -> 23
I25: WIP | J25: ='Calculated Stats'!C118 -> 30
A26: delivery allocation | outcomes | I26: done | J26: ='Calculated Stats'!C119 -> 26.5 | Q26: insight
A27: SUM | B27: =SUM(B29:B31) -> 18.5
B28: total | C28: % | Q28: healthy performance trend | R28: ='Calculated Stats'!C146 -> FALSE
A29: =_xlfn.CONCAT('Calculated Stats'!B127, "/", 'Calculated Stats'!B128) -> BAU/Improvement | B29: ='Calculated Stats'!C130 -> 11.5 | C29: =ROUND(B29/B$27*100,0) -> 62 | I29: BACKGROUND: capacity vs trend | Q29: achievable sprint goal | R29: ='Calculated Stats'!C145 -> FALSE
A30: Convergence | B30: =MATCH(A30, 'Calculated Stats'!B$36:B$45, 0) -> 3 | C30: =ROUND(B30/B$27*100,0) -> 16
A31: Project | B31: =MATCH(A31, 'Calculated Stats'!B$36:B$45, 0) -> 4 | C31: =ROUND(B31/B$27*100,0) -> 22 | J31: ='Calculated Stats'!C108 -> 79.5 | K31: total in sprint
I32: capacity trend | J32: ='Calculated Stats'!C143 -> 50
I33: sprint capacity | J33: ='Calculated Stats'!C140 -> 50
I37: work item granularity | Q37: delivery allocation | streams
Q38: total | R38: =SUM(R40:R44) -> 23.5
S39: %
I40: points | J40: ='Calculated Stats'!C134 -> 1.2 | Q40: Cloud | R40: =INDEX('Calculated Stats'!D$66:D$75, MATCH(Q40, 'Calculated Stats'!B$66:B$75, 0)) -> 9 | S40: =ROUND(R40/R$38*100,0) -> 38
I41: items | J41: 1 | Q41: Dataverse | R41: =INDEX('Calculated Stats'!D$66:D$75, MATCH(Q41, 'Calculated Stats'!B$66:B$75, 0)) -> 14.5 | S41: =ROUND(R41/R$38*100,0) -> 62
Q42: Architecture | R42: =INDEX('Calculated Stats'!D$66:D$75, MATCH(Q42, 'Calculated Stats'!B$66:B$75, 0)) -> 0 | S42: =ROUND(R42/R$38*100,0) -> 0
I43: total work items completed | J43: ='Calculated Stats'!E107 -> 23
I44: total story points completed | J44: ='Calculated Stats'!C107 -> 26.5
I48: unestimated work
J49: %
I50: % items | J50: ='Calculated Stats'!C135 -> 13
I52: total work items unestimated | J52: =GETPIVOTDATA("[Measures].[Count of Issue key]",#REF!) -> #REF!
...

Sheet Calculated Stats
B1: Calculated Stats
B2: stats calculated based on cleaned data
B6: Configure the labels you are interested in here only
B7: Labels | C7: Components
B8: BAU | C8: Architecture
B9: Improvement | C9: Cloud
B10: Convergence | C10: Dataverse
B11: Project
B12: 5 | C12: 5
B13: 6 | C13: 6
B14: 7 | C14: 7
B15: 8 | C15: 8
B16: 9 | C16: 9
B17: 10 | C17: 10
B20: Sprint Details
B21: Sprint name | C21: ='processed | data'!B6 -> Q24-4.8
B22: squad name | C22: ='processed | data'!B7 -> Architecture & Engineering
B23: sprint start date | C23: =TEXT('processed | data'!B8, "DD/MM/YYYY") -> 03/07/2024
B24: sprint end date | C24: =TEXT('processed | data'!B9, "DD/MM/YYYY") -> 18/07/2024
B32: Data in these tables is pulled in from processed | data sheet
B34: Streams (labels) | C34: story points
B35: DON’T EDIT THIS LIST (USE CONFIG ABOVE) | C35: total in sprint | D35: done
B36: =B8 -> BAU | C36: ='processed | data'!B17 -> 20.5 | D36: ='processed | data'!B28 -> 0
B37: =B9 -> Improvement | C37: ='processed | data'!B18 -> 0 | D37: ='processed | data'!B29 -> 11.5
B38: =B10 -> Convergence | C38: ='processed | data'!B19 -> 16.5 | D38: ='processed | data'!B30 -> 0
B39: =B11 -> Project | C39: ='processed | data'!B20 -> 41.5 | D39: ='processed | data'!B31 -> 5.5
B40: =B12 -> 5 | C40: ='processed | data'!B21 -> 0 | D40: ='processed | data'!B32 -> 9.5
B41: =B13 -> 6 | C41: ='processed | data'!B22 -> 0 | D41: ='processed | data'!B33 -> 0
B42: =B14 -> 7 | C42: ='processed | data'!B23 -> 0 | D42: ='processed | data'!B34 -> 0
B43: =B15 -> 8 | C43: ='processed | data'!B26 -> 0 | D43: ='processed | data'!B35 -> 0
B44: =B16 -> 9 | C44: ='processed | data'!B27 -> 0 | D44: ='processed | data'!B36 -> 0
B45: =B17 -> 10 | C45: ='processed | data'!B28 -> 0 | D45: ='processed | data'!B37 -> 0
B49: Streams (labels) | C49: throughput
B50: DON’T EDIT THIS LIST (USE CONFIG ABOVE) | C50: total in sprint | D50: done
B51: =B8 -> BAU | C51: ='processed | data'!B68 -> 20 | D51: ='processed | data'!B80 -> 9
B52: =B9 -> Improvement | C52: ='processed | data'!B69 -> 0 | D52: ='processed | data'!B81 -> 0
B53: =B10 -> Convergence | C53: ='processed | data'!B70 -> 14 | D53: ='processed | data'!B82 -> 4
B54: =B11 -> Project | C54: ='processed | data'!B71 -> 30 | D54: ='processed | data'!B83 -> 10
B55: =B12 -> 5 | C55: ='processed | data'!B72 -> 0 | D55: ='processed | data'!B84 -> 0
B56: =B13 -> 6 | C56: ='processed | data'!B73 -> 0 | D56: ='processed | data'!B85 -> 0
...

Sheet processed | data
A1: Processed Data
A2: calculated stats imported from csv
A4: Sprint Details
A5: Sprint Details | D5: csv field | E5: csv column index
A6: Sprint name | B6: {=IFERROR(INDEX('rawdata | iteration analysis'!$2:$2, E6), 0)} -> Q24-4.8 | D6: sprintName | E6: =MATCH(D6, 'rawdata | iteration analysis'!$1:$1, ) -> 1
A7: squad name | B7: {=IFERROR(INDEX('rawdata | iteration analysis'!$2:$2, E7), 0)} -> Architecture & Engineering | D7: squadName | E7: =MATCH(D7, 'rawdata | iteration analysis'!$1:$1, ) -> 2
A8: sprint start date | B8: {=IFERROR(INDEX('rawdata | iteration analysis'!$2:$2, E8), 0)} -> 45476 | D8: sprintDate_start | E8: =MATCH(D8, 'rawdata | iteration analysis'!$1:$1, ) -> 3
A9: sprint end date | B9: {=IFERROR(INDEX('rawdata | iteration analysis'!$2:$2, E9), 0)} -> 45491 | D9: sprintDate_end | E9: =MATCH(D9, 'rawdata | iteration analysis'!$1:$1, ) -> 4
A15: Metadata | D15: storyPoints
A16: Labels (total in sprint) | B16: value | D16: csv field | E16: csv column index
A17: ='Calculated Stats'!B8 -> BAU | B17: {=IFERROR(INDEX('rawdata | iteration analysis'!$2:$2, E17), 0)} -> 20.5 | D17: =_xlfn.CONCAT("labels_", A17,"_",D$15) -> labels_BAU_storyPoints | E17: =MATCH(D17, 'rawdata | iteration analysis'!$1:$1, ) -> 22
A18: ='Calculated Stats'!B9 -> Improvement | B18: {=IFERROR(INDEX('rawdata | iteration analysis'!$2:$2, E18), 0)} -> 0 | D18: =_xlfn.CONCAT("labels_", A18,"_",D$15) -> labels_Improvement_storyPoints | E18: =MATCH(D18, 'rawdata | iteration analysis'!$1:$1, ) -> #N/A
A19: ='Calculated Stats'!B10 -> Convergence | B19: {=IFERROR(INDEX('rawdata | iteration analysis'!$2:$2, E19), 0)} -> 16.5 | D19: =_xlfn.CONCAT("labels_", A19,"_",D$15) -> labels_Convergence_storyPoints | E19: =MATCH(D19, 'rawdata | iteration analysis'!$1:$1, ) -> 26
A20: ='Calculated Stats'!B11 -> Project | B20: {=IFERROR(INDEX('rawdata | iteration analysis'!$2:$2, E20), 0)} -> 41.5 | D20: =_xlfn.CONCAT("labels_", A20, "_",D$15) -> labels_Project_storyPoints | E20: =MATCH(D20, 'rawdata | iteration analysis'!$1:$1, ) -> 30
A21: ='Calculated Stats'!B12 -> 5 | B21: {=IFERROR(INDEX('rawdata | iteration analysis'!$2:$2, E21), 0)} -> 0 | D21: =_xlfn.CONCAT("labels_", A21,"_",D$15) -> labels_5_storyPoints | E21: =MATCH(D21, 'rawdata | iteration analysis'!$1:$1, ) -> #N/A
A22: ='Calculated Stats'!B13 -> 6 | B22: {=IFERROR(INDEX('rawdata | iteration analysis'!$2:$2, E22), 0)} -> 0 | D22: =_xlfn.CONCAT("labels_", A22, "_",D$15) -> labels_6_storyPoints | E22: =MATCH(D22, 'rawdata | iteration analysis'!$1:$1, ) -> #N/A
A23: ='Calculated Stats'!B14 -> 7 | B23: {=IFERROR(INDEX('rawdata | iteration analysis'!$2:$2, E23), 0)} -> 0 | D23: =_xlfn.CONCAT("labels_", A23,"_",D$15) -> labels_7_storyPoints | E23: =MATCH(D23, 'rawdata | iteration analysis'!$1:$1, ) -> #N/A
A24: ='Calculated Stats'!B15 -> 8 | B24: {=IFERROR(INDEX('rawdata | iteration analysis'!$2:$2, E24), 0)} -> 0 | D24: =_xlfn.CONCAT("labels_", A24,"_",D$15) -> labels_8_storyPoints | E24: =MATCH(D24, 'rawdata | iteration analysis'!$1:$1, ) -> #N/A
A25: ='Calculated Stats'!B16 -> 9 | B25: {=IFERROR(INDEX('rawdata | iteration analysis'!$2:$2, E25), 0)} -> 0 | D25: =_xlfn.CONCAT("labels_", A25,"_",D$15) -> labels_9_storyPoints | E25: =MATCH(D25, 'rawdata | iteration analysis'!$1:$1, ) -> #N/A
A26: ='Calculated Stats'!B17 -> 10 | B26: {=IFERROR(INDEX('rawdata | iteration analysis'!$2:$2, E26), 0)} -> 0 | D26: =_xlfn.CONCAT("labels_", A26,"_",D$15) -> labels_10_storyPoints | E26: =MATCH(D26, 'rawdata | iteration analysis'!$1:$1, ) -> #N/A
A28: Labels (done) | D28: csv field | E28: csv column index
A29: ='Calculated Stats'!B8 -> BAU | B29: {=IFERROR(INDEX('rawdata | iteration analysis'!$2:$2, E29), 0)} -> 11.5 | D29: =_xlfn.CONCAT("completedLabels_", A29,"_",D$15) -> completedLabels_BAU_storyPoints | E29: =MATCH(D29, 'rawdata | iteration analysis'!$1:$1, ) -> 54
A30: ='Calculated Stats'!B9 -> Improvement | B30: {=IFERROR(INDEX('rawdata | iteration analysis'!$2:$2, E30), 0)} -> 0 | D30: =_xlfn.CONCAT("completedLabels_", A30,"_",D$15) -> completedLabels_Improvement_storyPoints | E30: =MATCH(D30, 'rawdata | iteration analysis'!$1:$1, ) -> #N/A
A31: ='Calculated Stats'!B10 -> Convergence | B31: {=IFERROR(INDEX('rawdata | iteration analysis'!$2:$2, E31), 0)} -> 5.5 | D31: =_xlfn.CONCAT("completedLabels_", A31,"_",D$15) -> completedLabels_Convergence_storyPoints | E31: =MATCH(D31, 'rawdata | iteration analysis'!$1:$1, ) -> 58
A32: ='Calculated Stats'!B11 -> Project | B32: {=IFERROR(INDEX('rawdata | iteration analysis'!$2:$2, E32), 0)} -> 9.5 | D32: =_xlfn.CONCAT("completedLabels_", A32,"_",D$15) -> completedLabels_Project_storyPoints | E32: =MATCH(D32, 'rawdata | iteration analysis'!$1:$1, ) -> 62
A33: ='Calculated Stats'!B12 -> 5 | B33: {=IFERROR(INDEX('rawdata | iteration analysis'!$2:$2, E33), 0)} -> 0 | D33: =_xlfn.CONCAT("completedLabels_", A33,"_",D$15) -> completedLabels_5_storyPoints | E33: =MATCH(D33, 'rawdata | iteration analysis'!$1:$1, ) -> #N/A
A34: ='Calculated Stats'!B13 -> 6 | B34: {=IFERROR(INDEX('rawdata | iteration analysis'!$2:$2, E34), 0)} -> 0 | D34: =_xlfn.CONCAT("completedLabels_", A34,"_",D$15) -> completedLabels_6_storyPoints | E34: =MATCH(D34, 'rawdata | iteration analysis'!$1:$1, ) -> #N/A
A35: ='Calculated Stats'!B14 -> 7 | B35: {=IFERROR(INDEX('rawdata | iteration analysis'!$2:$2, E35), 0)} -> 0 | D35: =_xlfn.CONCAT("completedLabels_", A35,"_",D$15) -> completedLabels_7_storyPoints | E35: =MATCH(D35, 'rawdata | iteration analysis'!$1:$1, ) -> #N/A
A36: ='Calculated Stats'!B15 -> 8 | B36: {=IFERROR(INDEX('rawdata | iteration analysis'!$2:$2, E36), 0)} -> 0 | D36: =_xlfn.CONCAT("completedLabels_", A36,"_",D$15) -> completedLabels_8_storyPoints | E36: =MATCH(D36, 'rawdata | iteration analysis'!$1:$1, ) -> #N/A
A37: ='Calculated Stats'!B16 -> 9 | B37: {=IFERROR(INDEX('rawdata | iteration analysis'!$2:$2, E37), 0)} -> 0 | D37: =_xlfn.CONCAT("completedLabels_", A37,"_",D$15) -> completedLabels_9_storyPoints | E37: =MATCH(D37, 'rawdata | iteration analysis'!$1:$1, ) -> #N/A
A38: ='Calculated Stats'!B17 -> 10 | B38: {=IFERROR(INDEX('rawdata | iteration analysis'!$2:$2, E38), 0)} -> 0 | D38: =_xlfn.CONCAT("completedLabels_", A38,"_",D$15) -> completedLabels_10_storyPoints | E38: =MATCH(D38, 'rawdata | iteration analysis'!$1:$1, ) -> #N/A
A40: Components (total in sprint) | D40: csv field | E40: csv column index
A41: ='Calculated Stats'!C8 -> Architecture | B41: {=IFERROR(INDEX('rawdata | iteration analysis'!$2:$2, E41), 0)} -> 24 | D41: =_xlfn.CONCAT("components_", A41,"_",D$15) -> components_Architecture_storyPoints | E41: =MATCH(D41, 'rawdata | iteration analysis'!$1:$1, ) -> 50
A42: ='Calculated Stats'!C9 -> Cloud | B42: {=IFERROR(INDEX('rawdata | iteration analysis'!$2:$2, E42), 0)} -> 28.5 | D42: =_xlfn.CONCAT("components_", A42,"_",D$15) -> components_Cloud_storyPoints | E42: =MATCH(D42, 'rawdata | iteration analysis'!$1:$1, ) -> 48
A43: ='Calculated Stats'!C10 -> Dataverse | B43: {=IFERROR(INDEX('rawdata | iteration analysis'!$2:$2, E43), 0)} -> 24 | D43: =_xlfn.CONCAT("components_", A43,"_",D$15) -> components_Dataverse_storyPoints | E43: =MATCH(D43, 'rawdata | iteration analysis'!$1:$1, ) -> 46
A44: ='Calculated Stats'!C11 -> 0 | B44: {=IFERROR(INDEX('rawdata | iteration analysis'!$2:$2, E44), 0)} -> 0 | D44: =_xlfn.CONCAT("components_", A44,"_",D$15) -> components_0_storyPoints | E44: =MATCH(D44, 'rawdata | iteration analysis'!$1:$1, ) -> #N/A
A45: ='Calculated Stats'!C12 -> 5 | B45: {=IFERROR(INDEX('rawdata | iteration analysis'!$2:$2, E45), 0)} -> 0 | D45: =_xlfn.CONCAT("components_", A45,"_",D$15) -> components_5_storyPoints | E45: =MATCH(D45, 'rawdata | iteration analysis'!$1:$1, ) -> #N/A
A46: ='Calculated Stats'!C13 -> 6 | B46: {=IFERROR(INDEX('rawdata | iteration analysis'!$2:$2, E46), 0)} -> 0 | D46: =_xlfn.CONCAT("components_", A46,"_",D$15) -> components_6_storyPoints | E46: =MATCH(D46, 'rawdata | iteration analysis'!$1:$1, ) -> #N/A
A47: ='Calculated Stats'!C14 -> 7 | B47: {=IFERROR(INDEX('rawdata | iteration analysis'!$2:$2, E47), 0)} -> 0 | D47: =_xlfn.CONCAT("components_", A47,"_",D$15) -> components_7_storyPoints | E47: =MATCH(D47, 'rawdata | iteration analysis'!$1:$1, ) -> #N/A
A48: ='Calculated Stats'!C15 -> 8 | B48: {=IFERROR(INDEX('rawdata | iteration analysis'!$2:$2, E48), 0)} -> 0 | D48: =_xlfn.CONCAT("components_", A48,"_",D$15) -> components_8_storyPoints | E48: =MATCH(D48, 'rawdata | iteration analysis'!$1:$1, ) -> #N/A
...

Sheet rawdata | iteration analysis
A1: sprintName | B1: squadName | C1: sprintDate_start | D1: sprintDate_end | E1: sprintOverview_backlogSize_estimate | F1: sprintOverview_backlogSize_throughput | G1: sprintOverview_completedTotal_estimate | H1: sprintOverview_completedTotal_throughput | I1: sprintOverview_notCompletedInSprint_estimate | J1: sprintOverview_notCompletedInSprint_throughput | K1: sprintOverview_committedAtStartOfSprint_estimate | L1: sprintOverview_committedAtStartOfSprint_throughput | M1: sprintOverview_removedFromSprint_estimate | N1: sprintOverview_removedFromSprint_throughput | O1: sprintCompletion_notStarted_throughput | P1: sprintCompletion_notStarted_estimate | Q1: sprintCompletion_inProgress_throughput | R1: sprintCompletion_inProgress_estimate | S1: sprintCompletion_done_throughput | T1: sprintCompletion_done_estimate | U1: labels_BAU_count | V1: labels_BAU_storyPoints | W1: labels_FY24Q4-Committed_count | X1: labels_FY24Q4-Committed_storyPoints | Y1: labels_Convergence_count | Z1: labels_Convergence_storyPoints | AA1: labels_Cloud_count | AB1: labels_Cloud_storyPoints | AC1: labels_Project_count | AD1: labels_Project_storyPoints | AE1: labels_Dataverse_count | AF1: labels_Dataverse_storyPoints | AG1: labels_HESTAi_count | AH1: labels_HESTAi_storyPoints | AI1: labels_DEP-Resolution_count | AJ1: labels_DEP-Resolution_storyPoints | AK1: labels_CIT_count | AL1: labels_CIT_storyPoints | AM1: labels_INT-DEP.AE_count | AN1: labels_INT-DEP.AE_storyPoints | AO1: labels_FY25Q1-Committed_count | AP1: labels_FY25Q1-Committed_storyPoints | AQ1: labels_Integration_count | AR1: labels_Integration_storyPoints | AS1: components_Dataverse_count | AT1: components_Dataverse_storyPoints | AU1: components_Cloud_count | AV1: components_Cloud_storyPoints | AW1: components_Architecture_count | AX1: components_Architecture_storyPoints | AY1: components_Partner_count | AZ1: components_Partner_storyPoints | BA1: completedLabels_BAU_count | BB1: completedLabels_BAU_storyPoints | BC1: completedLabels_FY24Q4-Committed_count | BD1: completedLabels_FY24Q4-Committed_storyPoints | BE1: completedLabels_Convergence_count | BF1: completedLabels_Convergence_storyPoints | BG1: completedLabels_Cloud_count | BH1: completedLabels_Cloud_storyPoints | BI1: completedLabels_Project_count | BJ1: completedLabels_Project_storyPoints | BK1: completedLabels_Dataverse_count | BL1: completedLabels_Dataverse_storyPoints | BM1: completedLabels_HESTAi_count | BN1: completedLabels_HESTAi_storyPoints | BO1: completedLabels_CIT_count | BP1: completedLabels_CIT_storyPoints | BQ1: completedLabels_DEP-Resolution_count | BR1: completedLabels_DEP-Resolution_storyPoints | BS1: completedLabels_INT-DEP.AE_count | BT1: completedLabels_INT-DEP.AE_storyPoints | BU1: completedComponents_Dataverse_count | BV1: completedComponents_Dataverse_storyPoints | BW1: completedComponents_Cloud_count | BX1: completedComponents_Cloud_storyPoints | BY1: emergentWork_count | BZ1: emergentWork_storyPoints | CA1: metricConfidence_workitemGranularity | CB1: metricConfidence_unestimatedWorkPercentage | CC1: strategy_bauCapacityAllocationPercentage | CD1: sprintPlanning_targetCapacity_estimate | CE1: sprintPlanning_targetCapacity_throughput | CF1: trends_velocityTrends_estimate | CG1: trends_velocityTrends_throughput | CH1: insights_achievableSprintGoal_estimate | CI1: insights_achievableSprintGoal_throughput | CJ1: insights_healthyPerformanceTarget_estimate | CK1: insights_healthyPerformanceTarget_throughput
A2: Q24-4.8 | B2: Architecture & Engineering | C2: 45476 | D2: 45491 | E2: 79.5 | F2: 64 | G2: 26.5 | H2: 23 | I2: 53 | J2: 41 | K2: 72.5 | L2: 63 | M2: 15 | N2: 9 | O2: 19 | P2: 23 | Q2: 22 | R2: 30 | S2: 23 | T2: 26.5 | U2: 20 | V2: 20.5 | W2: 29 | X2: 34 | Y2: 14 | Z2: 16.5 | AA2: 2 | AB2: 1 | AC2: 30 | AD2: 41.5 | AE2: 5 | AF2: 6 | AG2: 8 | AH2: 11.5 | AI2: 3 | AJ2: 4 | AK2: 2 | AL2: 4 | AM2: 2 | AN2: 4 | AO2: 3 | AP2: 5 | AQ2: 1 | AR2: 5 | AS2: 23 | AT2: 24 | AU2: 24 | AV2: 28.5 | AW2: 16 | AX2: 24 | AY2: 1 | AZ2: 0 | BA2: 9 | BB2: 11.5 | BC2: 11 | BD2: 11.5 | BE2: 4 | BF2: 5.5 | BG2: 2 | BH2: 1 | BI2: 10 | BJ2: 9.5 | BK2: 4 | BL2: 4 | BM2: 1 | BN2: 0.5 | BO2: 1 | BP2: 3 | BQ2: 1 | BR2: 3 | BS2: 1 | BT2: 3 | BU2: 13 | BV2: 14.5 | BW2: 9 | BX2: 9 | BY2: 20 | BZ2: 20.5 | CA2: 1.2 | CB2: 13 | CC2: 30 | CD2: 50 | CE2: 50 | CF2: 50 | CG2: 50 | CH2: FALSE | CI2: FALSE | CJ2: FALSE | CK2: FALSE

Sheet REF | sample of csv field names
A1: sprintName
A2: squadName
A3: sprintDate_start
A4: sprintDate_end
A5: sprintOverview_backlogSize_estimate
A6: sprintOverview_backlogSize_throughput
A7: sprintOverview_completedTotal_estimate
A8: sprintOverview_completedTotal_throughput
A9: sprintOverview_notCompletedInSprint_estimate
A10: sprintOverview_notCompletedInSprint_throughput
A11: sprintOverview_committedAtStartOfSprint_estimate
A12: sprintOverview_committedAtStartOfSprint_throughput
... A1032281: insights_healthyPerformanceTarget_throughput
